[2023-02-05 23:37:02,103] {taskinstance.py:1179} INFO - Dependencies all met for <TaskInstance: 06_monitoring_trigger_rules.task_4 scheduled__2022-11-06T00:00:00+00:00 [queued]>
[2023-02-05 23:37:02,113] {taskinstance.py:1179} INFO - Dependencies all met for <TaskInstance: 06_monitoring_trigger_rules.task_4 scheduled__2022-11-06T00:00:00+00:00 [queued]>
[2023-02-05 23:37:02,113] {taskinstance.py:1376} INFO - 
--------------------------------------------------------------------------------
[2023-02-05 23:37:02,113] {taskinstance.py:1377} INFO - Starting attempt 1 of 3
[2023-02-05 23:37:02,113] {taskinstance.py:1378} INFO - 
--------------------------------------------------------------------------------
[2023-02-05 23:37:02,136] {taskinstance.py:1397} INFO - Executing <Task(PythonOperator): task_4> on 2022-11-06 00:00:00+00:00
[2023-02-05 23:37:02,139] {standard_task_runner.py:52} INFO - Started process 39328 to run task
[2023-02-05 23:37:02,144] {standard_task_runner.py:79} INFO - Running: ['airflow', 'tasks', 'run', '06_monitoring_trigger_rules', 'task_4', 'scheduled__2022-11-06T00:00:00+00:00', '--job-id', '292', '--raw', '--subdir', 'DAGS_FOLDER/06.2_monitoring_trigger_rules.py', '--cfg-path', '/tmp/tmpl1ajrag5', '--error-file', '/tmp/tmp9zeah5rq']
[2023-02-05 23:37:02,146] {standard_task_runner.py:80} INFO - Job 292: Subtask task_4
[2023-02-05 23:37:02,227] {task_command.py:371} INFO - Running <TaskInstance: 06_monitoring_trigger_rules.task_4 scheduled__2022-11-06T00:00:00+00:00 [running]> on host pc.
[2023-02-05 23:37:02,309] {taskinstance.py:1589} INFO - Exporting the following env vars:
AIRFLOW_CTX_DAG_OWNER=airflow
AIRFLOW_CTX_DAG_ID=06_monitoring_trigger_rules
AIRFLOW_CTX_TASK_ID=task_4
AIRFLOW_CTX_EXECUTION_DATE=2022-11-06T00:00:00+00:00
AIRFLOW_CTX_TRY_NUMBER=1
AIRFLOW_CTX_DAG_RUN_ID=scheduled__2022-11-06T00:00:00+00:00
[2023-02-05 23:37:02,310] {taskinstance.py:1909} ERROR - Task failed with exception
Traceback (most recent call last):
  File "/home/milo/13-airflow/airflowhome/airflowenv/lib/python3.9/site-packages/airflow/operators/python.py", line 171, in execute
    return_value = self.execute_callable()
  File "/home/milo/13-airflow/airflowhome/airflowenv/lib/python3.9/site-packages/airflow/operators/python.py", line 189, in execute_callable
    return self.python_callable(*self.op_args, **self.op_kwargs)
  File "/home/milo/13-airflow/airflowhome/dags/06.2_monitoring_trigger_rules.py", line 9, in my_function
    raise Exception
Exception
[2023-02-05 23:37:02,315] {taskinstance.py:1415} INFO - Marking task as UP_FOR_RETRY. dag_id=06_monitoring_trigger_rules, task_id=task_4, execution_date=20221106T000000, start_date=20230206T043702, end_date=20230206T043702
[2023-02-05 23:37:02,332] {standard_task_runner.py:92} ERROR - Failed to execute job 292 for task task_4 (; 39328)
[2023-02-05 23:37:02,355] {local_task_job.py:156} INFO - Task exited with return code 1
[2023-02-05 23:37:02,398] {local_task_job.py:273} INFO - 0 downstream tasks scheduled from follow-on schedule check
