[2023-02-06 00:11:01,555] {taskinstance.py:1179} INFO - Dependencies all met for <TaskInstance: 06_monitoring_trigger_rules.task_4 scheduled__2022-11-01T00:00:00+00:00 [queued]>
[2023-02-06 00:11:01,565] {taskinstance.py:1179} INFO - Dependencies all met for <TaskInstance: 06_monitoring_trigger_rules.task_4 scheduled__2022-11-01T00:00:00+00:00 [queued]>
[2023-02-06 00:11:01,565] {taskinstance.py:1376} INFO - 
--------------------------------------------------------------------------------
[2023-02-06 00:11:01,565] {taskinstance.py:1377} INFO - Starting attempt 9 of 9
[2023-02-06 00:11:01,565] {taskinstance.py:1378} INFO - 
--------------------------------------------------------------------------------
[2023-02-06 00:11:01,587] {taskinstance.py:1397} INFO - Executing <Task(PythonOperator): task_4> on 2022-11-01 00:00:00+00:00
[2023-02-06 00:11:01,590] {standard_task_runner.py:52} INFO - Started process 40416 to run task
[2023-02-06 00:11:01,595] {standard_task_runner.py:79} INFO - Running: ['airflow', 'tasks', 'run', '06_monitoring_trigger_rules', 'task_4', 'scheduled__2022-11-01T00:00:00+00:00', '--job-id', '379', '--raw', '--subdir', 'DAGS_FOLDER/06.2_monitoring_trigger_rules.py', '--cfg-path', '/tmp/tmpmyea1n4n', '--error-file', '/tmp/tmp3qp5ejza']
[2023-02-06 00:11:01,596] {standard_task_runner.py:80} INFO - Job 379: Subtask task_4
[2023-02-06 00:11:01,679] {task_command.py:371} INFO - Running <TaskInstance: 06_monitoring_trigger_rules.task_4 scheduled__2022-11-01T00:00:00+00:00 [running]> on host pc.
[2023-02-06 00:11:01,754] {taskinstance.py:1589} INFO - Exporting the following env vars:
AIRFLOW_CTX_DAG_OWNER=airflow
AIRFLOW_CTX_DAG_ID=06_monitoring_trigger_rules
AIRFLOW_CTX_TASK_ID=task_4
AIRFLOW_CTX_EXECUTION_DATE=2022-11-01T00:00:00+00:00
AIRFLOW_CTX_TRY_NUMBER=9
AIRFLOW_CTX_DAG_RUN_ID=scheduled__2022-11-01T00:00:00+00:00
[2023-02-06 00:11:01,755] {taskinstance.py:1909} ERROR - Task failed with exception
Traceback (most recent call last):
  File "/home/milo/13-airflow/airflowhome/airflowenv/lib/python3.9/site-packages/airflow/operators/python.py", line 171, in execute
    return_value = self.execute_callable()
  File "/home/milo/13-airflow/airflowhome/airflowenv/lib/python3.9/site-packages/airflow/operators/python.py", line 189, in execute_callable
    return self.python_callable(*self.op_args, **self.op_kwargs)
  File "/home/milo/13-airflow/airflowhome/dags/06.2_monitoring_trigger_rules.py", line 9, in my_function
    raise Exception
Exception
[2023-02-06 00:11:01,762] {taskinstance.py:1415} INFO - Marking task as FAILED. dag_id=06_monitoring_trigger_rules, task_id=task_4, execution_date=20221101T000000, start_date=20230206T051101, end_date=20230206T051101
[2023-02-06 00:11:01,777] {standard_task_runner.py:92} ERROR - Failed to execute job 379 for task task_4 (; 40416)
[2023-02-06 00:11:01,806] {local_task_job.py:156} INFO - Task exited with return code 1
[2023-02-06 00:11:01,852] {local_task_job.py:273} INFO - 0 downstream tasks scheduled from follow-on schedule check
