[2023-02-08 00:31:57,843] {taskinstance.py:1179} INFO - Dependencies all met for <TaskInstance: 09_Xcoms.task_3_pull scheduled__2022-12-06T00:00:00+00:00 [queued]>
[2023-02-08 00:31:57,855] {taskinstance.py:1179} INFO - Dependencies all met for <TaskInstance: 09_Xcoms.task_3_pull scheduled__2022-12-06T00:00:00+00:00 [queued]>
[2023-02-08 00:31:57,855] {taskinstance.py:1376} INFO - 
--------------------------------------------------------------------------------
[2023-02-08 00:31:57,855] {taskinstance.py:1377} INFO - Starting attempt 1 of 1
[2023-02-08 00:31:57,855] {taskinstance.py:1378} INFO - 
--------------------------------------------------------------------------------
[2023-02-08 00:31:57,876] {taskinstance.py:1397} INFO - Executing <Task(PythonOperator): task_3_pull> on 2022-12-06 00:00:00+00:00
[2023-02-08 00:31:57,880] {standard_task_runner.py:52} INFO - Started process 52475 to run task
[2023-02-08 00:31:57,887] {standard_task_runner.py:79} INFO - Running: ['airflow', 'tasks', 'run', '09_Xcoms', 'task_3_pull', 'scheduled__2022-12-06T00:00:00+00:00', '--job-id', '1203', '--raw', '--subdir', 'DAGS_FOLDER/09_xcoms.py', '--cfg-path', '/tmp/tmpy2i427zr', '--error-file', '/tmp/tmpkq0_mo_7']
[2023-02-08 00:31:57,888] {standard_task_runner.py:80} INFO - Job 1203: Subtask task_3_pull
[2023-02-08 00:31:57,975] {task_command.py:371} INFO - Running <TaskInstance: 09_Xcoms.task_3_pull scheduled__2022-12-06T00:00:00+00:00 [running]> on host pc.
[2023-02-08 00:31:58,064] {taskinstance.py:1589} INFO - Exporting the following env vars:
AIRFLOW_CTX_DAG_OWNER=airflow
AIRFLOW_CTX_DAG_ID=09_Xcoms
AIRFLOW_CTX_TASK_ID=task_3_pull
AIRFLOW_CTX_EXECUTION_DATE=2022-12-06T00:00:00+00:00
AIRFLOW_CTX_TRY_NUMBER=1
AIRFLOW_CTX_DAG_RUN_ID=scheduled__2022-12-06T00:00:00+00:00
[2023-02-08 00:31:58,073] {taskinstance.py:1909} ERROR - Task failed with exception
Traceback (most recent call last):
  File "/home/milo/13-airflow/airflowhome/airflowenv/lib/python3.9/site-packages/airflow/operators/python.py", line 171, in execute
    return_value = self.execute_callable()
  File "/home/milo/13-airflow/airflowhome/airflowenv/lib/python3.9/site-packages/airflow/operators/python.py", line 189, in execute_callable
    return self.python_callable(*self.op_args, **self.op_kwargs)
  File "/home/milo/13-airflow/airflowhome/dags/09_xcoms.py", line 11, in myfunction
    print(int(context["ti"].xcom_pull(task_ids="task_3_pull")) -6)
TypeError: int() argument must be a string, a bytes-like object or a number, not 'NoneType'
[2023-02-08 00:31:58,078] {taskinstance.py:1415} INFO - Marking task as FAILED. dag_id=09_Xcoms, task_id=task_3_pull, execution_date=20221206T000000, start_date=20230208T053157, end_date=20230208T053158
[2023-02-08 00:31:58,094] {standard_task_runner.py:92} ERROR - Failed to execute job 1203 for task task_3_pull (int() argument must be a string, a bytes-like object or a number, not 'NoneType'; 52475)
[2023-02-08 00:31:58,139] {local_task_job.py:156} INFO - Task exited with return code 1
[2023-02-08 00:31:58,173] {local_task_job.py:273} INFO - 0 downstream tasks scheduled from follow-on schedule check
