[2023-02-05 23:41:23,934] {taskinstance.py:1179} INFO - Dependencies all met for <TaskInstance: 06_monitoring_trigger_rules.task_4 scheduled__2022-11-15T00:00:00+00:00 [queued]>
[2023-02-05 23:41:23,945] {taskinstance.py:1179} INFO - Dependencies all met for <TaskInstance: 06_monitoring_trigger_rules.task_4 scheduled__2022-11-15T00:00:00+00:00 [queued]>
[2023-02-05 23:41:23,946] {taskinstance.py:1376} INFO - 
--------------------------------------------------------------------------------
[2023-02-05 23:41:23,946] {taskinstance.py:1377} INFO - Starting attempt 2 of 3
[2023-02-05 23:41:23,946] {taskinstance.py:1378} INFO - 
--------------------------------------------------------------------------------
[2023-02-05 23:41:23,967] {taskinstance.py:1397} INFO - Executing <Task(PythonOperator): task_4> on 2022-11-15 00:00:00+00:00
[2023-02-05 23:41:23,969] {standard_task_runner.py:52} INFO - Started process 39672 to run task
[2023-02-05 23:41:23,975] {standard_task_runner.py:79} INFO - Running: ['airflow', 'tasks', 'run', '06_monitoring_trigger_rules', 'task_4', 'scheduled__2022-11-15T00:00:00+00:00', '--job-id', '366', '--raw', '--subdir', 'DAGS_FOLDER/06.2_monitoring_trigger_rules.py', '--cfg-path', '/tmp/tmp18vbg4on', '--error-file', '/tmp/tmpnynxk_vs']
[2023-02-05 23:41:23,976] {standard_task_runner.py:80} INFO - Job 366: Subtask task_4
[2023-02-05 23:41:24,053] {task_command.py:371} INFO - Running <TaskInstance: 06_monitoring_trigger_rules.task_4 scheduled__2022-11-15T00:00:00+00:00 [running]> on host pc.
[2023-02-05 23:41:24,126] {taskinstance.py:1589} INFO - Exporting the following env vars:
AIRFLOW_CTX_DAG_OWNER=airflow
AIRFLOW_CTX_DAG_ID=06_monitoring_trigger_rules
AIRFLOW_CTX_TASK_ID=task_4
AIRFLOW_CTX_EXECUTION_DATE=2022-11-15T00:00:00+00:00
AIRFLOW_CTX_TRY_NUMBER=2
AIRFLOW_CTX_DAG_RUN_ID=scheduled__2022-11-15T00:00:00+00:00
[2023-02-05 23:41:24,127] {taskinstance.py:1909} ERROR - Task failed with exception
Traceback (most recent call last):
  File "/home/milo/13-airflow/airflowhome/airflowenv/lib/python3.9/site-packages/airflow/operators/python.py", line 171, in execute
    return_value = self.execute_callable()
  File "/home/milo/13-airflow/airflowhome/airflowenv/lib/python3.9/site-packages/airflow/operators/python.py", line 189, in execute_callable
    return self.python_callable(*self.op_args, **self.op_kwargs)
  File "/home/milo/13-airflow/airflowhome/dags/06.2_monitoring_trigger_rules.py", line 9, in my_function
    raise Exception
Exception
[2023-02-05 23:41:24,133] {taskinstance.py:1415} INFO - Marking task as UP_FOR_RETRY. dag_id=06_monitoring_trigger_rules, task_id=task_4, execution_date=20221115T000000, start_date=20230206T044123, end_date=20230206T044124
[2023-02-05 23:41:24,151] {standard_task_runner.py:92} ERROR - Failed to execute job 366 for task task_4 (; 39672)
[2023-02-05 23:41:24,186] {local_task_job.py:156} INFO - Task exited with return code 1
[2023-02-05 23:41:24,227] {local_task_job.py:273} INFO - 0 downstream tasks scheduled from follow-on schedule check
